Traceback (most recent call last):
  File "/data/dydtkddhkdwk/anaconda3/envs/BERTRANKING/lib/python3.8/site-packages/transformers/utils/hub.py", line 399, in cached_file
    resolved_file = hf_hub_download(
  File "/data/dydtkddhkdwk/anaconda3/envs/BERTRANKING/lib/python3.8/site-packages/huggingface_hub/utils/_validators.py", line 106, in _inner_fn
    validate_repo_id(arg_value)
  File "/data/dydtkddhkdwk/anaconda3/envs/BERTRANKING/lib/python3.8/site-packages/huggingface_hub/utils/_validators.py", line 154, in validate_repo_id
    raise HFValidationError(
huggingface_hub.errors.HFValidationError: Repo id must be in the form 'repo_name' or 'namespace/repo_name': './repos/scibert_scivocab_cased'. Use `repo_type` argument if needed.

The above exception was the direct cause of the following exception:

Traceback (most recent call last):
  File "repos/OXIDE/load_predict.py", line 35, in <module>
    model = BERTTextClassifier(nanoparticle_classes=6, subject_classes=6, bert_model_name=bert_model_name)
  File "/data/dydtkddhkdwk/repos/OXIDE/train.py", line 22, in __init__
    self.bert_nanoparticle = BertForSequenceClassification.from_pretrained(bert_model_name, num_labels=nanoparticle_classes)
  File "/data/dydtkddhkdwk/anaconda3/envs/BERTRANKING/lib/python3.8/site-packages/transformers/modeling_utils.py", line 3051, in from_pretrained
    resolved_config_file = cached_file(
  File "/data/dydtkddhkdwk/anaconda3/envs/BERTRANKING/lib/python3.8/site-packages/transformers/utils/hub.py", line 463, in cached_file
    raise EnvironmentError(
OSError: Incorrect path_or_model_id: './repos/scibert_scivocab_cased'. Please provide either the path to a local folder or the repo_id of a model on the Hub.
