Traceback (most recent call last):
  File "repos/OXIDE/analysis.py", line 5, in <module>
    with open(dir, "r") as f:
FileNotFoundError: [Errno 2] No such file or directory: '../repos/OXIDE/prediction_log_962399.txt'
